Traceback (most recent call last):
  File "/Users/esamsoe/miniforge3/envs/mpg-horses/lib/python3.13/site-packages/pandas/core/indexes/base.py", line 3805, in get_loc
    return self._engine.get_loc(casted_key)
           ~~~~~~~~~~~~~~~~~~~~^^^^^^^^^^^^
  File "index.pyx", line 167, in pandas._libs.index.IndexEngine.get_loc
  File "index.pyx", line 196, in pandas._libs.index.IndexEngine.get_loc
  File "pandas/_libs/hashtable_class_helper.pxi", line 7081, in pandas._libs.hashtable.PyObjectHashTable.get_item
  File "pandas/_libs/hashtable_class_helper.pxi", line 7089, in pandas._libs.hashtable.PyObjectHashTable.get_item
KeyError: 0

The above exception was the direct cause of the following exception:

Traceback (most recent call last):
  File "/Users/esamsoe/Projects/Dev/MPG_Ranch/mpg-horses/src/horse_detection.py", line 1175, in <module>
    main(args)
    ~~~~^^^^^^
  File "/Users/esamsoe/Projects/Dev/MPG_Ranch/mpg-horses/src/horse_detection.py", line 1019, in main
    train_loader, test_loader = create_image_dataloaders(
                                ~~~~~~~~~~~~~~~~~~~~~~~~^
        dataset=dataset,
        ^^^^^^^^^^^^^^^^
    ...<3 lines>...
        device=device,
        ^^^^^^^^^^^^^^
    )
    ^
  File "/Users/esamsoe/Projects/Dev/MPG_Ranch/mpg-horses/src/horse_detection.py", line 335, in create_image_dataloaders
    labels = [horse_dataset[i][1] for i in range(dataset_size)]
              ~~~~~~~~~~~~~^^^
  File "/Users/esamsoe/Projects/Dev/MPG_Ranch/mpg-horses/src/horse_detection.py", line 207, in __getitem__
    item = self.dataset[idx]
           ~~~~~~~~~~~~^^^^^
  File "/Users/esamsoe/miniforge3/envs/mpg-horses/lib/python3.13/site-packages/pandas/core/frame.py", line 4102, in __getitem__
    indexer = self.columns.get_loc(key)
  File "/Users/esamsoe/miniforge3/envs/mpg-horses/lib/python3.13/site-packages/pandas/core/indexes/base.py", line 3812, in get_loc
    raise KeyError(key) from err
KeyError: 0
Random seed set to 42
Using device: mps
Loading dataset from cache: data/cached_datasets/mpg-ranch_horse-detection.parquet
Loaded cached dataset with 12780 samples
Dataset size: 12780
Dataset columns: ['idx', 'Presence', 'Zone', 'Period', 'Recency', 'datetime_groundtruth', 'datetime_aerialsurvey', 'Latitude', 'Longitude', 'Easting', 'Northing', 'Ellipsoidal_height', 'orthomosaic', 'tile_path', 'observation_offset', 'encoded_tile', '__index_level_0__', 'image_base64']
Using full dataset
Using 0 workers for data loading
Error in main function: 0
